Workbook

Sheet Confusion
A1: Confusion matrix dei modelli - PC e Board STM32
A3: ONNX originale | E3: ONNX quantizzato | I3: TFLite originale | M3: Board
B4: Predetto 0 | C4: Predetto 1 | F4: Predetto 0 | G4: Predetto 1 | J4: Predetto 0 | K4: Predetto 1 | N4: Predetto 0 | O4: Predetto 1
A5: Vero 0 | B5: 735 | C5: 15 | E5: Vero 0 | F5: 750 | G5: 0 | I5: Vero 0 | J5: 735 | K5: 15 | M5: Vero 0 | N5: 4 | O5: 1
A6: Vero 1 | B6: 47 | C6: 703 | E6: Vero 1 | F6: 244 | G6: 506 | I6: Vero 1 | J6: 47 | K6: 703 | M6: Vero 1 | N6: 1 | O6: 4

Sheet Tempi inferenza
A1: Tempi di inferenza per frame/batch (secondi) - PC e Board STM32
A3: Frame/Batch | B3: ONNX originale | C3: ONNX quantizzato | D3: TFLite originale | E3: Board STM32 [s]
A4: 0 | B4: 0.0107298 | C4: 0.0195602 | D4: 0.0195172 | E4: 22.972544
A5: 1 | B5: 0.0088618 | C5: 0.0095985 | D5: 0.0160712 | E5: 22.972539
A6: 2 | B6: 0.0072941 | C6: 0.0079118 | D6: 0.0139403 | E6: 22.972559
A7: 3 | B7: 0.0059847 | C7: 0.0091782 | D7: 0.0141557 | E7: 22.972559
A8: 4 | B8: 0.0069181 | C8: 0.007877 | D8: 0.0143918 | E8: 22.972557
A9: 5 | B9: 0.0071138 | C9: 0.0103549 | D9: 0.0127195 | E9: 22.97256
A10: 6 | B10: 0.0075271 | C10: 0.0096467 | D10: 0.0124184 | E10: 22.972559
A11: 7 | B11: 0.0068942 | C11: 0.0092545 | D11: 0.0153231 | E11: 22.972557
A12: 8 | B12: 0.0063202 | C12: 0.0098885 | D12: 0.0142882 | E12: 22.97256
A13: 9 | B13: 0.0071851 | C13: 0.0087557 | D13: 0.0142754 | E13: 22.972558
A14: 10 | B14: 0.0059404 | C14: 0.0117811 | D14: 0.0135901 | E14: 22.972556
A15: 11 | B15: 0.0064229 | C15: 0.0118651 | D15: 0.0152266 | E15: 22.972559
... A133: 129 | B133: 0.0066826 | C133: 0.0110785 | D133: 0.0114559 | E133: 22.972556
A134: 130 | B134: 0.006517 | C134: 0.0113592 | D134: 0.019354
A135: 131 | B135: 0.0059345 | C135: 0.0104678 | D135: 0.0125086
A136: 132 | B136: 0.0070615 | C136: 0.0095855 | D136: 0.0188599
A137: 133 | B137: 0.0060167 | C137: 0.0108582 | D137: 0.0130617
A138: 134 | B138: 0.006254 | C138: 0.0118727 | D138: 0.0140294
A139: 135 | B139: 0.0063395 | C139: 0.0104627 | D139: 0.0146423
A140: 136 | B140: 0.0059272 | C140: 0.0108555 | D140: 0.0135971
A141: 137 | B141: 0.0078581 | C141: 0.0083949 | D141: 0.0150655
A142: 138 | B142: 0.0077833 | C142: 0.0114983 | D142: 0.0135678
A143: 139 | B143: 0.0080105 | C143: 0.012471 | D143: 0.0168335
A144: 140 | B144: 0.0070025 | C144: 0.0114861 | D144: 0.0109363
A145: 141 | B145: 0.0079268 | C145: 0.0082997 | D145: 0.0150403
... A19503: 19499 | B19503: 0.0116964 | C19503: 0.0092554 | D19503: 0.0154101

Sheet Riepilogo
A1: Confronto complessivo modelli ONNX / TFLite / Board STM32
A3: Metrica | B3: ONNX originale | C3: ONNX quantizzato | D3: TFLite originale | E3: Board STM32 (10 file) | F3: Modello | G3: Accuracy | H3: Recall | I3: F1-score
A4: TN | B4: =Confusion!B5 -> 735 | C4: =Confusion!F5 -> 750 | D4: =Confusion!J5 -> 735 | E4: 4 | F4: ONNX originale | G4: =B11 -> 0.95866667 | H4: =B13 -> 0.93733333 | I4: =B15 -> 0.95776567
A5: FP | B5: =Confusion!C5 -> 15 | C5: =Confusion!G5 -> 0 | D5: =Confusion!K5 -> 15 | E5: 1 | F5: ONNX quantizzato | G5: =C11 -> 0.83733333 | H5: =C13 -> 0.67466667 | I5: =C15 -> 0.80573248
A6: FN | B6: =Confusion!B6 -> 47 | C6: =Confusion!F6 -> 244 | D6: =Confusion!J6 -> 47 | E6: 1 | F6: TFLite originale | G6: =D11 -> 0.95866667 | H6: =D13 -> 0.93733333 | I6: =D15 -> 0.95776567
A7: TP | B7: =Confusion!C6 -> 703 | C7: =Confusion!G6 -> 506 | D7: =Confusion!K6 -> 703 | E7: 4
A8: Totale | B8: =SUM(B4:B7) -> 1500 | C8: =SUM(C4:C7) -> 1500 | D8: =SUM(D4:D7) -> 1500 | E8: 10
F9: Modello | G9: Tempo medio [ms]
A10: Metriche di classificazione | F10: ONNX originale | G10: =B18 -> 8.6439539
A11: Accuracy | B11: =(B4+B7)/B8 -> 0.95866667 | C11: =(C4+C7)/C8 -> 0.83733333 | D11: =(D4+D7)/D8 -> 0.95866667 | E11: 0.8 | F11: ONNX quantizzato | G11: =C18 -> 9.4349291
A12: Precision | B12: =B7/(B7+B5) -> 0.97910864 | C12: =C7/(C7+C5) -> 1 | D12: =D7/(D7+D5) -> 0.97910864 | E12: 0.8 | F12: TFLite originale | G12: =D18 -> 14.761891
A13: Recall / Sensitivity | B13: =B7/(B7+B6) -> 0.93733333 | C13: =C7/(C7+C6) -> 0.67466667 | D13: =D7/(D7+D6) -> 0.93733333 | E13: 0.8
A14: Specificity | B14: =B4/(B4+B5) -> 0.98 | C14: =C4/(C4+C5) -> 1 | D14: =D4/(D4+D5) -> 0.98 | E14: 0.8
A15: F1-score | B15: =2*B12*B13/(B12+B13) -> 0.95776567 | C15: =2*C12*C13/(C12+C13) -> 0.80573248 | D15: =2*D12*D13/(D12+D13) -> 0.95776567 | E15: 0.8
A17: Tempi di inferenza
A18: Media per frame [ms] | B18: =AVERAGE('Tempi inferenza'!B4:B19503)*1000 -> 8.6439539 | C18: =AVERAGE('Tempi inferenza'!C4:C19503)*1000 -> 9.4349291 | D18: =AVERAGE('Tempi inferenza'!D4:D19503)*1000 -> 14.761891 | E18: 22972.559
A19: Mediana [ms] | B19: =MEDIAN('Tempi inferenza'!B4:B19503)*1000 -> 8.6994 | C19: =MEDIAN('Tempi inferenza'!C4:C19503)*1000 -> 9.3824 | D19: =MEDIAN('Tempi inferenza'!D4:D19503)*1000 -> 14.5848 | E19: 22972.559
A20: Deviazione standard [ms] | B20: 1.4817245 | C20: 1.1559961 | D20: 3.0447241 | E20: 0.014736477
A21: Minimo [ms] | B21: =MIN('Tempi inferenza'!B4:B19503)*1000 -> 5.8762 | C21: =MIN('Tempi inferenza'!C4:C19503)*1000 -> 7.5107 | D21: =MIN('Tempi inferenza'!D4:D19503)*1000 -> 10.1963 | E21: 22972.511
A22: Massimo [ms] | B22: =MAX('Tempi inferenza'!B4:B19503)*1000 -> 74.0581 | C22: =MAX('Tempi inferenza'!C4:C19503)*1000 -> 56.3021 | D22: =MAX('Tempi inferenza'!D4:D19503)*1000 -> 133.6536 | E22: 22972.657
A23: Tempo totale [s] | B23: =SUM('Tempi inferenza'!B4:B19503) -> 168.5571 | C23: =SUM('Tempi inferenza'!C4:C19503) -> 183.98112 | D23: =SUM('Tempi inferenza'!D4:D19503) -> 287.85687 | E23: 2986.4327
A25: Score e frame error
A26: Score medio | B26: 0.025370627 | C26: 0.029069446 | D26: 0.02537065 | E26: 0.0290429
A27: Score mediano | B27: 0.004388355 | C27: 0.012531793 | D27: 0.00438837 | E27: 0.012915
A28: Score minimo | B28: 0.0038723962 | C28: 0.011591099 | D28: 0.0038724465 | E28: 0.011945
A29: Score massimo | B29: 0.11006953 | C29: 0.098907375 | D29: 0.11006961 | E29: 0.082412
A31: Dettaglio Board STM32 - inferenza parziale su 10 file
A32: Voce | B32: Valore
A33: Rete analizzata | B33: tcn_hif_autoencoder_quant_sani
A34: File presenti nel dataset | B34: 1500
A35: File realmente inferenziati | B35: 10
A36: Frame per file | B36: 13
A37: Inferenze eseguite | B37: 130
A38: Stima per file [min] | B38: 4.9773878
A39: Stima su 1500 file [giorni] | B39: 5.184779
A41: File/Chunk | B41: Score | C41: Label predetta | D41: Label vera | E41: Esito
A42: 0 | B42: 0.012472 | C42: 0 | D42: 0 | E42: OK
A43: 1 | B43: 0.012086 | C43: 0 | D43: 0 | E43: OK
A44: 2 | B44: 0.012085 | C44: 0 | D44: 0 | E44: OK
A45: 3 | B45: 0.011945 | C45: 0 | D45: 0 | E45: OK
...
